<?xml version="1.0" encoding="utf-8" ?>
<mujoco>
    <option timestep="0.002" viscosity="0.001">
        <flag multiccd="enable"/>
    </option>
    <default>
        <geom friction="0.04 0.001 0.0001"/>
    </default>
    <worldbody>
        <body name="floor" pos="0.5 0 -0.1">
            <geom type="box" name="floor" size="1 1 0.1" rgba="0.02 0.02 0.05 1"/>
        </body>
        <body name="robot" pos="0.02 0.0 0.055">
            <geom type="box" name="top_finger" pos="0 0.06 0" euler="0 0 45" size="0.1 0.01 0.05" rgba="0.8 0.5 0.5 1"
                  friction="0.04 0.001 0.0001"/>
            <geom type="box" name="bottom_finger" pos="0 -0.06 0" euler="0 0 -45" size="0.1 0.01 0.05"
                  rgba="0.8 0.5 0.5 1" friction="0.04 0.001 0.0001"/>
            <joint type="slide" name="x" pos="0 0 0" axis="1 0 0" damping="2"/>
            <joint type="slide" name="y" pos="0 0 0" axis="0 1 0" damping="2"/>
            <joint type="hinge" name="z" pos="0 0 0" axis="0 0 1" damping="2"/>
        </body>
        <body name="object" pos="0.05 0 0.031">
            <geom type="cylinder" name="base" size="0.05 0.03" rgba="0.2 0.8 0.8 1" friction="0.001 0.001 0.0001"/>
            <joint type="free" damping="0.01"/>
        </body>
    </worldbody>
    <actuator>
        <velocity name="x" joint="x" kv="50"/>
        <velocity name="y" joint="y" kv="50"/>
        <velocity name="z" joint="z" kv="2"/>
    </actuator>
</mujoco>